ERROR 2025-06-05 23:33:00,747 log 1504518 129453516888960 Internal Server Error: /api/v1/users/
Traceback (most recent call last):
  File "/home/jose/.local/lib/python3.10/site-packages/django/db/backends/utils.py", line 105, in _execute
    return self.cursor.execute(sql, params)
psycopg2.errors.UndefinedColumn: column "updated_at" of relation "api_user" does not exist
LINE 1: INSERT INTO "api_user" ("id", "created_at", "updated_at", "n...
                                                    ^


The above exception was the direct cause of the following exception:

Traceback (most recent call last):
  File "/home/jose/.local/lib/python3.10/site-packages/django/core/handlers/exception.py", line 55, in inner
    response = get_response(request)
  File "/home/jose/.local/lib/python3.10/site-packages/django/core/handlers/base.py", line 197, in _get_response
    response = wrapped_callback(request, *callback_args, **callback_kwargs)
  File "/home/jose/.local/lib/python3.10/site-packages/django/views/decorators/csrf.py", line 65, in _view_wrapper
    return view_func(request, *args, **kwargs)
  File "/home/jose/.local/lib/python3.10/site-packages/django/views/generic/base.py", line 104, in view
    return self.dispatch(request, *args, **kwargs)
  File "/home/jose/.pyenv/versions/3.10.9/lib/python3.10/site-packages/rest_framework/views.py", line 509, in dispatch
    response = self.handle_exception(exc)
  File "/home/jose/.pyenv/versions/3.10.9/lib/python3.10/site-packages/rest_framework/views.py", line 469, in handle_exception
    self.raise_uncaught_exception(exc)
  File "/home/jose/.pyenv/versions/3.10.9/lib/python3.10/site-packages/rest_framework/views.py", line 480, in raise_uncaught_exception
    raise exc
  File "/home/jose/.pyenv/versions/3.10.9/lib/python3.10/site-packages/rest_framework/views.py", line 506, in dispatch
    response = handler(request, *args, **kwargs)
  File "/home/jose/.pyenv/versions/3.10.9/lib/python3.10/site-packages/rest_framework/generics.py", line 246, in post
    return self.create(request, *args, **kwargs)
  File "/home/jose/.pyenv/versions/3.10.9/lib/python3.10/site-packages/rest_framework/mixins.py", line 19, in create
    self.perform_create(serializer)
  File "/home/jose/PruebaTecnica/todolist/api/views.py", line 98, in perform_create
    user = serializer.save()
  File "/home/jose/.pyenv/versions/3.10.9/lib/python3.10/site-packages/rest_framework/serializers.py", line 208, in save
    self.instance = self.create(validated_data)
  File "/home/jose/.pyenv/versions/3.10.9/lib/python3.10/site-packages/rest_framework/serializers.py", line 989, in create
    instance = ModelClass._default_manager.create(**validated_data)
  File "/home/jose/.local/lib/python3.10/site-packages/django/db/models/manager.py", line 87, in manager_method
    return getattr(self.get_queryset(), name)(*args, **kwargs)
  File "/home/jose/.local/lib/python3.10/site-packages/django/db/models/query.py", line 663, in create
    obj.save(force_insert=True, using=self.db)
  File "/home/jose/.local/lib/python3.10/site-packages/django/db/models/base.py", line 902, in save
    self.save_base(
  File "/home/jose/.local/lib/python3.10/site-packages/django/db/models/base.py", line 1008, in save_base
    updated = self._save_table(
  File "/home/jose/.local/lib/python3.10/site-packages/django/db/models/base.py", line 1169, in _save_table
    results = self._do_insert(
  File "/home/jose/.local/lib/python3.10/site-packages/django/db/models/base.py", line 1210, in _do_insert
    return manager._insert(
  File "/home/jose/.local/lib/python3.10/site-packages/django/db/models/manager.py", line 87, in manager_method
    return getattr(self.get_queryset(), name)(*args, **kwargs)
  File "/home/jose/.local/lib/python3.10/site-packages/django/db/models/query.py", line 1864, in _insert
    return query.get_compiler(using=using).execute_sql(returning_fields)
  File "/home/jose/.local/lib/python3.10/site-packages/django/db/models/sql/compiler.py", line 1882, in execute_sql
    cursor.execute(sql, params)
  File "/home/jose/.local/lib/python3.10/site-packages/django/db/backends/utils.py", line 79, in execute
    return self._execute_with_wrappers(
  File "/home/jose/.local/lib/python3.10/site-packages/django/db/backends/utils.py", line 92, in _execute_with_wrappers
    return executor(sql, params, many, context)
  File "/home/jose/.local/lib/python3.10/site-packages/django/db/backends/utils.py", line 100, in _execute
    with self.db.wrap_database_errors:
  File "/home/jose/.local/lib/python3.10/site-packages/django/db/utils.py", line 91, in __exit__
    raise dj_exc_value.with_traceback(traceback) from exc_value
  File "/home/jose/.local/lib/python3.10/site-packages/django/db/backends/utils.py", line 105, in _execute
    return self.cursor.execute(sql, params)
django.db.utils.ProgrammingError: column "updated_at" of relation "api_user" does not exist
LINE 1: INSERT INTO "api_user" ("id", "created_at", "updated_at", "n...
                                                    ^

